Workbook

Sheet SEED CHARACTERS
A1: NAME | B1: INSTAGRAM HANDLE | C1: INSTAGRAM PROFILE URL | D1: FOLLOWER COUNT | E1: NUMBER OF POSTS | F1: POSTING FREQUENCY (posts/week, last 14d) | G1: POSTS LAST 7D | H1: AVERAGE LIKES (last 12 posts) | I1: AVERAGE COMMENTS (last 12 posts) | J1: ENGAGEMENT RATE | K1: ESTIMATED ENGAGEMENT LEVEL | L1: LAST POST DATE | M1: RECENT ACTIVITY | N1: FIRST VISIBLE POST / APPROXIMATE DEBUT | O1: CHARACTER BIO | P1: PERSONALITY / ARCHETYPE | Q1: VISUAL STYLE | R1: CONTENT STYLE | S1: RECURRING JOKES / THEMES | T1: MOST SUCCESSFUL POSTS | U1: NOTABLE REELS | V1: VIRAL MOMENTS | W1: BRAND COLLABS (if visible) | X1: OTHER FICTIONAL / AI CHARACTERS THEY INTERACT WITH | Y1: TOKEN / TICKER - on Instagram | Z1: TOKEN / TICKER - user supplied | AA1: TOKEN / TICKER - external (non-IG) | AB1: WEBSITE / LINK IN BIO | AC1: IS THE ACCOUNT ACTIVE? | AD1: WHY THIS CHARACTER IS INTERESTING | AE1: PARODY / IDENTITY DISAMBIGUATION | AF1: ALT / COPYCAT ACCOUNTS FOUND | AG1: FAME SCORE | AH1: MOMENTUM SCORE | AI1: INDEX CANDIDATE SCORE | AJ1: Evidence links (key posts)
A2: Jean Phil | B2: jean_philanthrope | C2: https://www.instagram.com/jean_philanthrope/ | D2: =INDEX('ALL CANDIDATES'!$K$2:$K$63,MATCH($B2,'ALL CANDIDATES'!$C$2:$C$63,0)) -> 241147 | E2: =INDEX('ALL CANDIDATES'!$M$2:$M$63,MATCH($B2,'ALL CANDIDATES'!$C$2:$C$63,0)) -> 12 | F2: =INDEX('ALL CANDIDATES'!$W$2:$W$63,MATCH($B2,'ALL CANDIDATES'!$C$2:$C$63,0)) -> 2 | G2: =INDEX('ALL CANDIDATES'!$T$2:$T$63,MATCH($B2,'ALL CANDIDATES'!$C$2:$C$63,0)) -> 2 | H2: =INDEX('ALL CANDIDATES'!$X$2:$X$63,MATCH($B2,'ALL CANDIDATES'!$C$2:$C$63,0)) -> 297994 | I2: =INDEX('ALL CANDIDATES'!$Z$2:$Z$63,MATCH($B2,'ALL CANDIDATES'!$C$2:$C$63,0)) -> 7823 | J2: =INDEX('ALL CANDIDATES'!$AC$2:$AC$63,MATCH($B2,'ALL CANDIDATES'!$C$2:$C$63,0)) -> 1.2681767 | K2: =INDEX('ALL CANDIDATES'!$AD$2:$AD$63,MATCH($B2,'ALL CANDIDATES'!$C$2:$C$63,0)) -> Very high | L2: =INDEX('ALL CANDIDATES'!$R$2:$R$63,MATCH($B2,'ALL CANDIDATES'!$C$2:$C$63,0)) -> 46302 | M2: OBSERVED: last post 2026-10-07 (Paris Fashion Week / @stellamccartney, 5,981 likes). 2 posts in last 7 days, 4 in last 14. Cadence and engagement falling since the 09-18..09-22 peak. | N2: OBSERVED: first post 2026-09-17 - 'Jab, crochet. T'as senti le danger? 😤' (35,972 likes). Full history (12/12) loaded. External (non-IG): Sprites.ai says the account was created June 2025 and renamed several times - UNKNOWN on IG. | O2: OBSERVED (bio verbatim): Oui Madame. | P2: OBSERVED: catchphrase 'Oui Madame.'; French captions; shadowboxing ('Jab, crochet. T'as senti le danger?'). INFERRED: suave, deadpan French gentleman-fighter / ladies' man | Q2: OBSERVED (grid screenshot): blond bowl/bob haircut, curled moustache, freckles, brown tweed suit + tie; real-world Paris locations | R2: OBSERVED: 12/12 Reels; short vertical clips, French-language captions, music-driven | S2: OBSERVED: 'Oui Madame.' sign-off on most captions; boxing/shadowboxing; Paris landmarks (Tour Eiffel); fashion (Paris Fashion Week, Double G) | T2: OBSERVED: 1) https://www.instagram.com/p/Ddb0QUyqnhG/ 2026-09-19 - 1,708,185 likes / 53,119 comments ('Elle m'appelle le soir...'); 2) https://www.instagram.com/p/Ddb4D8_qH_E/ 2026-09-18 - 921,019 / 15,560 (same lyric caption); 3) https://www.instagram.com/p/DdeBU0CK14n/ 2026-09-19 - 309,612 / 8,147 ('She feels safe with the man.') | U2: OBSERVED: https://www.instagram.com/p/DdmGsuNidFV/ 'Double G. Oui Madame' 219,931 likes; https://www.instagram.com/p/DdjeRwjqH5R/ 'Do you always dress this sharp? Oui Madame.' 195,109; https://www.instagram.com/p/DdhLkjpib7a/ 'Bonjour' 110,763; debut https://www.instagram.com/p/DdZ3IkKiiXx/ 35,972. All 12 posts are Reels; view counts not exposed (UNKNOWN). | V2: OBSERVED: 1.7M-like reel on day 3 of the account (2026-09-19); average 500,084 likes/post in week 1 (7 posts). INFERRED: the template that spawned the wave (rival Archibald Brown debuted 09-20, Abu Shalab 09-25, Benjamin Stachio 09-27). | W2: OBSERVED: tags @stellamccartney (Paris Fashion Week 2026 post) and @lafeve7 - no paid-partnership label captured; UNKNOWN whether paid | X2: OBSERVED (inbound): @archibald_brown (9 mentions - 'come to London and find out…', 'you're next'), @brigittemacaron_ (4 - 'La Jeanconde', 'your father'), @imranpoppadumb (4), @derek.mercer.2006 (2), @dequavious_von (2), @jadeorlhabit_ (bio 'Oui Monsieur… @jean_philanthrope Love U 💋'). Jean's own posts tag no other AI characters. | Y2: OBSERVED: NONE observed in bio/captions | Z2: $JEAN | AA2: $JEANPHIL (pump.fun, Solana) per Dexerto/Sprites.ai - NOT on IG profile | AB2: (none) - story highlight 'Contact' | AC2: YES - OBSERVED last post 2026-10-07 (2 days before capture); slowing (2 posts/7d). | AD2: INFERRED: Patient zero of the Sep-2026 AI-character wave: 1.7M-like reel within 2 days of debut; the hub most other characters tag or call out. | AE2: Original fictional character (no real-person namesake identified). Not to be confused with impostor/promo account @jeanphilanthrope.co ('Evil Twin'). | AF2: @jeanphilanthrope.co (250,667 followers, 'Evil Twin… Create Videos Just Like Me', ~336 likes/post - EXCLUDED); @jean_philanthroope; @phil_john_jean (copycat, 11K); @jeanphilbonjour (fan). | AG2: =INDEX('ALL CANDIDATES'!$BJ$2:$BJ$63,MATCH($B2,'ALL CANDIDATES'!$C$2:$C$63,0)) -> 63.7 | AH2: =INDEX('ALL CANDIDATES'!$BP$2:$BP$63,MATCH($B2,'ALL CANDIDATES'!$C$2:$C$63,0)) -> 53.3 | AI2: =INDEX('ALL CANDIDATES'!$BS$2:$BS$63,MATCH($B2,'ALL CANDIDATES'!$C$2:$C$63,0)) -> 72.3 | AJ2: https://www.instagram.com/p/DdZ3IkKiiXx/ debut https://www.instagram.com/p/Ddb0QUyqnhG/ top https://www.instagram.com/p/Ddb4D8_qH_E/ https://www.instagram.com/p/DdeBU0CK14n/ https://www.instagram.com/p/DeMqmuiiY6J/ latest (PFW/Stella McCartney) https://www.instagram.com/p/Dd_4AYBiSwh/ @lafeve7
A3: Benjamin Stachio | B3: benjamin_stachio | C3: https://www.instagram.com/benjamin_stachio/ | D3: =INDEX('ALL CANDIDATES'!$K$2:$K$63,MATCH($B3,'ALL CANDIDATES'!$C$2:$C$63,0)) -> 101097 | E3: =INDEX('ALL CANDIDATES'!$M$2:$M$63,MATCH($B3,'ALL CANDIDATES'!$C$2:$C$63,0)) -> 15 | F3: =INDEX('ALL CANDIDATES'!$W$2:$W$63,MATCH($B3,'ALL CANDIDATES'!$C$2:$C$63,0)) -> 6 | G3: =INDEX('ALL CANDIDATES'!$T$2:$T$63,MATCH($B3,'ALL CANDIDATES'!$C$2:$C$63,0)) -> 6 | H3: =INDEX('ALL CANDIDATES'!$X$2:$X$63,MATCH($B3,'ALL CANDIDATES'!$C$2:$C$63,0)) -> 8999 | I3: =INDEX('ALL CANDIDATES'!$Z$2:$Z$63,MATCH($B3,'ALL CANDIDATES'!$C$2:$C$63,0)) -> 575 | J3: =INDEX('ALL CANDIDATES'!$AC$2:$AC$63,MATCH($B3,'ALL CANDIDATES'!$C$2:$C$63,0)) -> 0.094701129 | K3: =INDEX('ALL CANDIDATES'!$AD$2:$AD$63,MATCH($B3,'ALL CANDIDATES'!$C$2:$C$63,0)) -> Very high | L3: =INDEX('ALL CANDIDATES'!$R$2:$R$63,MATCH($B3,'ALL CANDIDATES'!$C$2:$C$63,0)) -> 46303 | M3: OBSERVED: last post 2026-10-08 ('About last night 🍎', 627 likes). 6 posts in 7 days. 10-07 pinned announcement: single 'Shut It' released on streaming; 10-07 teaser 'Something big and fun is coming'. | N3: OBSERVED: first post 2026-09-27 - 'Clearing my head' (10,315 likes). Full history (15/15) loaded. | O3: OBSERVED (bio verbatim): Hello Darling / ⚠️No crypto affiliation yet⚠️ | P3: OBSERVED: 'Hello Darling'; travel/dance diary captions ('Visiting Rio de Janeiro', 'Dressed for the meeting'). INFERRED: polite, oblivious party gentleman | Q3: OBSERVED: triple-curl hair swirl + huge curled moustache, oversized neck, white shirt, navy tie, mustard trousers; real-world crowds (bar, Rio, Washington Monument) | R3: OBSERVED: 15/15 Reels; crowd-dance clips | S3: OBSERVED: dancing in crowds; travel (Brazil, Rio, Washington); 'About last night'; music single 'Shut It' announced 10-07 | T3: OBSERVED: 1) https://www.instagram.com/p/Dd2joiwTDJv/ 2026-09-29 'Dancing with friends' - 846,425 likes / 76,277 comments (pinned); 2) https://www.instagram.com/p/Dd4BE9nMR7M/ 2026-09-29 'About last night.' - 43,249 / 2,514; 3) https://www.instagram.com/p/Dd4zsK4sap8/ 2026-09-29 'Visiting Rio de Janeiro' - 22,710 / 925 | U3: OBSERVED: https://www.instagram.com/p/DeMs_zftQSm/ song release 'Shut It' (8,115 likes, pinned); https://www.instagram.com/p/Dd6Q8eVNeBn/ 'Made some friends in Brazil' 9,993 (pinned); https://www.instagram.com/p/Dd1byg2OwdD/ 'Working on my jabs.' 8,690. All 15 posts are Reels. | V3: OBSERVED: bar-dance reel (09-29) - 846K likes and 76K comments, the highest comment count of any seed post. External (non-IG): Dexerto 2026-09-30 reports an X repost by @teddybearisms passing 1.5M views and Grok calling it 'almost certainly AI'. | W3: UNKNOWN - none visible | X3: OBSERVED: none - no tags/mentions of other characters in 15 posts; no inbound mentions captured. | Y3: OBSERVED: NONE - bio explicitly says 'No crypto affiliation yet' | Z3: $STACHE | AA3: None per Dexerto (2026-09-30) | AB3: (none) | AC3: YES - OBSERVED last post 2026-10-08; 6 posts in last 7 days. | AD3: INFERRED: Most visually distinctive body-horror-comedy design of the wave; first character to move into music (single 'Shut It'). | AE3: Original fictional character; no real-person namesake identified. | AF3: @benjamin_stachiio (78 followers, copycat), @benjaminstachio, @darlingbenj, @benjamin_stachin (search results, not reviewed). | AG3: =INDEX('ALL CANDIDATES'!$BJ$2:$BJ$63,MATCH($B3,'ALL CANDIDATES'!$C$2:$C$63,0)) -> 50.9 | AH3: =INDEX('ALL CANDIDATES'!$BP$2:$BP$63,MATCH($B3,'ALL CANDIDATES'!$C$2:$C$63,0)) -> 61.7 | AI3: =INDEX('ALL CANDIDATES'!$BS$2:$BS$63,MATCH($B3,'ALL CANDIDATES'!$C$2:$C$63,0)) -> 59.8 | AJ3: https://www.instagram.com/p/DdzqxONPLaG/ debut https://www.instagram.com/p/Dd2joiwTDJv/ viral https://www.instagram.com/p/Dd4BE9nMR7M/ https://www.instagram.com/p/DeMs_zftQSm/ song 'Shut It' https://www.instagram.com/p/DeMc0YJBHjU/ teaser
A4: Lord Farquaad (parody account) | B4: lord.farquaad.sol | C4: https://www.instagram.com/lord.farquaad.sol/ | D4: =INDEX('ALL CANDIDATES'!$K$2:$K$63,MATCH($B4,'ALL CANDIDATES'!$C$2:$C$63,0)) -> 102526 | E4: =INDEX('ALL CANDIDATES'!$M$2:$M$63,MATCH($B4,'ALL CANDIDATES'!$C$2:$C$63,0)) -> 57 | F4: =INDEX('ALL CANDIDATES'!$W$2:$W$63,MATCH($B4,'ALL CANDIDATES'!$C$2:$C$63,0)) -> 25.5 | G4: =INDEX('ALL CANDIDATES'!$T$2:$T$63,MATCH($B4,'ALL CANDIDATES'!$C$2:$C$63,0)) -> 26 | H4: =INDEX('ALL CANDIDATES'!$X$2:$X$63,MATCH($B4,'ALL CANDIDATES'!$C$2:$C$63,0)) -> 2389 | I4: =INDEX('ALL CANDIDATES'!$Z$2:$Z$63,MATCH($B4,'ALL CANDIDATES'!$C$2:$C$63,0)) -> 38 | J4: =INDEX('ALL CANDIDATES'!$AC$2:$AC$63,MATCH($B4,'ALL CANDIDATES'!$C$2:$C$63,0)) -> 0.023672044 | K4: =INDEX('ALL CANDIDATES'!$AD$2:$AD$63,MATCH($B4,'ALL CANDIDATES'!$C$2:$C$63,0)) -> High | L4: =INDEX('ALL CANDIDATES'!$R$2:$R$63,MATCH($B4,'ALL CANDIDATES'!$C$2:$C$63,0)) -> 46304 | M4: OBSERVED: last post 2026-10-09 (capture day); 26 posts in last 7 days (~3-4/day). Captions now carry '#higgsfieldpartner'. Engagement down from 50,981 avg (09-24..30) to 4,870 avg (10-05..09). | N4: OBSERVED: first post 2026-09-25 (full 57-post history loaded on first pass; earliest captured codes: 09-26 'You buggin' / 'You know I had to hop on this trend'). | O4: OBSERVED (bio verbatim): Some of you may die, but that is a sacrifice I am willing to make / Email: lordfarquaadbusiness@gmail.com / Made with @higgsfield.ai | P4: OBSERVED: bio quotes the film villain's line; captions 'You buggin', 'Feeling fresh', 'Goodnight everyone (say it back)'. INFERRED: pompous tiny tyrant who loves TikTok dance trends | Q4: OBSERVED: black page-boy bob, burgundy medieval tunic/cape, filmed in modern settings (metro, night city) | R4: OBSERVED: 57/57 Reels; trend-dance clips; ~3-4 posts/day | S4: OBSERVED: hopping on dance trends ('You know I had to hop on this trend'); morning dances; milestone thanks ('Thank you for 40k!!') | T4: OBSERVED: 1) https://www.instagram.com/p/DdwhswgBSFq/ 2026-09-26 'Feeling fresh' - 379,725 likes / 2,844 comments; 2) https://www.instagram.com/p/Ddzz7F1hYlR/ 09-27 'Feeling smooth' - 137,053 / 667; 3) https://www.instagram.com/p/Dd3h3r_hnY0/ 09-29 'Early morning dance' - 88,544 / 698 | U4: OBSERVED: https://www.instagram.com/p/Dd4wdxZh3fs/ 'Thank you for 40k!!' 85,156; https://www.instagram.com/p/DdxIVkvB4XF/ 'Hitting this dance every morning' 70,551; https://www.instagram.com/p/DeOsvhjhDoP/ sponsored '#higgsfieldpartner' 8,642. 57/57 Reels. | V4: OBSERVED: 379K-like reel on day 2; '40k' milestone post 09-29; follower count 102.5K by 10-09. | W4: OBSERVED: '#higgsfieldpartner' tags on October captions = Higgsfield AI partnership; 'Made with @higgsfield.ai' in bio | X4: OBSERVED: none (only @higgsfield.ai / @higgsfield.creators / @higgsfield.soul - AI tool accounts). | Y4: OBSERVED: NONE in bio/captions; handle suffix '.sol' suggests Solana link (INFERRED) | Z4: $SHORTKING | AA4: UNKNOWN | AB4: (none) | AC4: YES - OBSERVED most active seed (posted on capture day; 26 posts/7d). | AD4: INFERRED: Highest posting cadence of any seed and an explicit AI-tool sponsorship - shows the brand-deal business model; borrowed IP limits index suitability. | AE4: PARODY of the DreamWorks 'Shrek' villain Lord Farquaad (third-party fictional IP). This account is NOT affiliated with DreamWorks; the bio quotes the film. IP/brand risk for any index product. | AF4: @lord__.farquaad, @l.o.r.d._.farquaad, @lordfarquaad20, @lordfarquaad.93 (search results; fan/meme accounts, not reviewed). | AG4: =INDEX('ALL CANDIDATES'!$BJ$2:$BJ$63,MATCH($B4,'ALL CANDIDATES'!$C$2:$C$63,0)) -> 51.5 | AH4: =INDEX('ALL CANDIDATES'!$BP$2:$BP$63,MATCH($B4,'ALL CANDIDATES'!$C$2:$C$63,0)) -> 64.4 | AI4: =INDEX('ALL CANDIDATES'!$BS$2:$BS$63,MATCH($B4,'ALL CANDIDATES'!$C$2:$C$63,0)) -> 59.3 | AJ4: https://www.instagram.com/p/DdwhswgBSFq/ top https://www.instagram.com/p/Ddzz7F1hYlR/ https://www.instagram.com/p/Dd4wdxZh3fs/ 40k milestone https://www.instagram.com/p/DeOsvhjhDoP/ #higgsfieldpartner https://www.instagram.com/p/DdvPCA8hQ63/ early
A5: Archibald Brown | B5: archibald_brown | C5: https://www.instagram.com/archibald_brown/ | D5: =INDEX('ALL CANDIDATES'!$K$2:$K$63,MATCH($B5,'ALL CANDIDATES'!$C$2:$C$63,0)) -> 131892 | E5: =INDEX('ALL CANDIDATES'!$M$2:$M$63,MATCH($B5,'ALL CANDIDATES'!$C$2:$C$63,0)) -> 56 | F5: =INDEX('ALL CANDIDATES'!$W$2:$W$63,MATCH($B5,'ALL CANDIDATES'!$C$2:$C$63,0)) -> 12.5 | G5: =INDEX('ALL CANDIDATES'!$T$2:$T$63,MATCH($B5,'ALL CANDIDATES'!$C$2:$C$63,0)) -> 5 | H5: =INDEX('ALL CANDIDATES'!$X$2:$X$63,MATCH($B5,'ALL CANDIDATES'!$C$2:$C$63,0)) -> 1302 | I5: =INDEX('ALL CANDIDATES'!$Z$2:$Z$63,MATCH($B5,'ALL CANDIDATES'!$C$2:$C$63,0)) -> 28 | J5: =INDEX('ALL CANDIDATES'!$AC$2:$AC$63,MATCH($B5,'ALL CANDIDATES'!$C$2:$C$63,0)) -> 0.010084008 | K5: =INDEX('ALL CANDIDATES'!$AD$2:$AD$63,MATCH($B5,'ALL CANDIDATES'!$C$2:$C$63,0)) -> Medium | L5: =INDEX('ALL CANDIDATES'!$R$2:$R$63,MATCH($B5,'ALL CANDIDATES'!$C$2:$C$63,0)) -> 46302 | M5: OBSERVED: last post 2026-10-07 ('Who…', 260 likes). 5 posts in 7 days. October storyline: fake UFC signing ('Thanks for this opportunity @danawhite', pinned 10-05) and call-out of Abu Nutty + Jean Phil (10-05). | N5: OBSERVED: first post 2026-09-20 - '0.5 speed' (9,949 likes). Full history (56/56) loaded - 3 days after Jean Phil's debut. | O5: OBSERVED (bio verbatim): DM if you need the 101 on throwing hands? 🥊 | P5: OBSERVED: coaching/fight talk ('101 on throwing hands', 'Quick 101'), call-outs ('@jean_philanthrope come to London and find out…'). INFERRED: cocky London boxer, Jean Phil's nemesis | Q5: OBSERVED: chestnut bowl cut, thin moustache, beige suit + tie; pinned UFC-contract photo; staged photo with a Mike Tyson likeness | R5: OBSERVED: 50 Reels + 6 photos/carousels; highlights 'Going pro', 'Getting him' | S5: OBSERVED: rivalry with Jean Phil; fake UFC career ('Thanks for this opportunity @danawhite'); 'Casper was the warm-up, @abunuttyofficial @jean_philanthrope, you're next' (10-05) | T5: OBSERVED: 1) https://www.instagram.com/p/DdmQOpyMNfr/ 2026-09-22 'Send me a dm for coaching' - 1,106,935 likes / 11,486 comments; 2) https://www.instagram.com/p/Ddlj-kosQ2h/ 09-22 '@jean_philanthrope come to London and find out…' - 196,416 / 4,432; 3) https://www.instagram.com/p/DdodwfSsRBx/ 09-23 'Flowing' - 71,382 / 1,143 | U5: OBSERVED: https://www.instagram.com/p/DdhzWDAM0F7/ '02:00 sesh' 54,754; https://www.instagram.com/p/Ddh3VsKi8vN/ 53,879 / 5,102 comments; https://www.instagram.com/p/DeIXFGUMxmL/ 'Casper was the warm-up, @abunuttyofficial @jean_philanthrope, you're next.' (10-05). 50 Reels + 6 photos. | V5: OBSERVED: 1.1M-like reel on day 3 (09-22) and the Jean Phil call-out the same day; pre-09-24 average 90,924 likes/post (18 posts). | W5: UNKNOWN - real fighters/Dana White are tagged as parody, no partnership label captured | X5: OBSERVED: OUT -> @jean_philanthrope (9; rivalry), @abunuttyofficial (3; call-out). IN <- @percival_ashcrofttt (3). Also tags real fighters/execs as storyline props (@anthonyjoshua, @jonnybones, @miketyson, @danawhite, @rodtang_jimungnon) - NOT real collaborations. | Y5: OBSERVED: NONE observed | Z5: UNKNOWN | AA5: $ARCHIBROWN per Dexerto/Sprites.ai - NOT on IG profile | AB5: archibaldbrown.com (+ Threads @archibald_brown) | AC5: YES - OBSERVED last post 2026-10-07; engagement low (~1-2K likes). | AD5: INFERRED: The storyline engine of the wave: rivalry with Jean Phil, cross-over call-outs to the AI-animal fighters (Abu Nutty, Casper). Strong lore, weak recent engagement. | AE5: Original fictional character (no real-person namesake identified). Real athletes appear only as tagged/AI-generated props; they are not involved. | AF5: @archibaldbrown3, @sir_archibaldfrenchie, @chroniclesofarchibaldbrown, @archeezmo (search results - unrelated or copycats). | AG5: =INDEX('ALL CANDIDATES'!$BJ$2:$BJ$63,MATCH($B5,'ALL CANDIDATES'!$C$2:$C$63,0)) -> 54.5 | AH5: =INDEX('ALL CANDIDATES'!$BP$2:$BP$63,MATCH($B5,'ALL CANDIDATES'!$C$2:$C$63,0)) -> 54.8 | AI5: =INDEX('ALL CANDIDATES'!$BS$2:$BS$63,MATCH($B5,'ALL CANDIDATES'!$C$2:$C$63,0)) -> 68.5 | AJ5: https://www.instagram.com/p/Ddhr_xBsuRK/ debut https://www.instagram.com/p/DdmQOpyMNfr/ top https://www.instagram.com/p/Ddlj-kosQ2h/ Jean call-out https://www.instagram.com/p/DeIXFGUMxmL/ 'you're next' https://www.instagram.com/p/DeIXZFdsCGd/ UFC 'opportunity' https://www.instagram.com/p/DdmINpvsuGs/ 'Mike met the man himself'
A6: Abu Shalab | B6: abu.shalab | C6: https://www.instagram.com/abu.shalab/ | D6: =INDEX('ALL CANDIDATES'!$K$2:$K$63,MATCH($B6,'ALL CANDIDATES'!$C$2:$C$63,0)) -> 531003 | E6: =INDEX('ALL CANDIDATES'!$M$2:$M$63,MATCH($B6,'ALL CANDIDATES'!$C$2:$C$63,0)) -> 27 | F6: =INDEX('ALL CANDIDATES'!$W$2:$W$63,MATCH($B6,'ALL CANDIDATES'!$C$2:$C$63,0)) -> 13.5 | G6: =INDEX('ALL CANDIDATES'!$T$2:$T$63,MATCH($B6,'ALL CANDIDATES'!$C$2:$C$63,0)) -> 11 | H6: =INDEX('ALL CANDIDATES'!$X$2:$X$63,MATCH($B6,'ALL CANDIDATES'!$C$2:$C$63,0)) -> 22069 | I6: =INDEX('ALL CANDIDATES'!$Z$2:$Z$63,MATCH($B6,'ALL CANDIDATES'!$C$2:$C$63,0)) -> 578 | J6: =INDEX('ALL CANDIDATES'!$AC$2:$AC$63,MATCH($B6,'ALL CANDIDATES'!$C$2:$C$63,0)) -> 0.042649477 | K6: =INDEX('ALL CANDIDATES'!$AD$2:$AD$63,MATCH($B6,'ALL CANDIDATES'!$C$2:$C$63,0)) -> High | L6: =INDEX('ALL CANDIDATES'!$R$2:$R$63,MATCH($B6,'ALL CANDIDATES'!$C$2:$C$63,0)) -> 46303 | M6: OBSERVED: last post 2026-10-08 ('Whats up guys !', 1,086 likes). 11 posts in 7 days; October average ~5-30K likes vs ~281K in the first 6 days. | N6: OBSERVED: first post 2026-09-25 - 'Habibi got hands' (30,379 likes). Full history (27/27) loaded. | O6: OBSERVED (bio verbatim): Dancer | Actor | Comedian / Road to 1M followers 😁 (0.52/1M) / Official $ABU👇 | P6: OBSERVED: 'Dancer | Actor | Comedian'; emoji-only captions, 'Heeywa', 'Habibi got hands'. INFERRED: carefree uncle-dancer | Q6: OBSERVED: white thobe, black bob wig, thick moustache; Dubai skyline, cars, airplanes | R6: OBSERVED: 26 Reels + 1 carousel | S6: OBSERVED: dancing anywhere (Disco time, DJ Abu, Abu Verstappen F1 parody); 'Road to 1M' follower goal; $ABU on-chain announcement | T6: OBSERVED: 1) https://www.instagram.com/p/Dduf1zGNri-/ 2026-09-25 'Throwback to when i won red bull dance' - 1,392,520 likes / 16,271 comments; 2) https://www.instagram.com/p/DdxCLS5NMRz/ 09-26 '🏡🕺' - 874,373 / 27,821; 3) https://www.instagram.com/p/DdyLrNpt3UU/ 09-27 'Disco time 😉' - 526,745 / 11,279 | U6: OBSERVED: https://www.instagram.com/p/Dd4WBQrt48X/ '🫶🕺' 289,729 / 32,186 comments; https://www.instagram.com/p/DdzcjsYtSxs/ 'A pump might be fun' 162,781; https://www.instagram.com/p/DeEbl6aNLnv/ 'Abu Verstappen 🏎️' 81,356 (best October post). | V6: OBSERVED: 1.39M-like reel on debut day; ~531K followers in 14 days (bio shows 'Road to 1M followers (0.52/1M)'). | W6: UNKNOWN - none visible | X6: OBSERVED: IN <- @imranpoppadumb (2). No outbound character tags. Clone-style accounts in the same archetype: @abu.yalla, @abdoul.cheqri. | Y6: OBSERVED: $ABU (bio + 10-02 carousel '$ABU Officially on Chain 🚀') | Z6: $ABUJAB | AA6: UNKNOWN | AB6: join.pump.fun/HSag/wsvnmbjs (pump.fun referral) | AC6: YES - OBSERVED last post 2026-10-08; 11 posts/7d. | AD6: INFERRED: Biggest audience among seeds (531K in 14 days) and the clearest IG-native token link ($ABU + pump.fun link in bio). | AE6: Original fictional character (Gulf/Arab 'uncle' archetype). Not a real performer as far as Instagram shows; 'won red bull dance' is an in-character joke (no Red Bull tag). | AF6: @abushalab.official, @abu__shalab, @abu_shalab11, @abu_shalab_ (search results - not reviewed). | AG6: =INDEX('ALL CANDIDATES'!$BJ$2:$BJ$63,MATCH($B6,'ALL CANDIDATES'!$C$2:$C$63,0)) -> 63.2 | AH6: =INDEX('ALL CANDIDATES'!$BP$2:$BP$63,MATCH($B6,'ALL CANDIDATES'!$C$2:$C$63,0)) -> 80.2 | AI6: =INDEX('ALL CANDIDATES'!$BS$2:$BS$63,MATCH($B6,'ALL CANDIDATES'!$C$2:$C$63,0)) -> 71.7 | AJ6: https://www.instagram.com/p/DduMth6NxfU/ debut https://www.instagram.com/p/Dduf1zGNri-/ top https://www.instagram.com/p/DdxCLS5NMRz/ https://www.instagram.com/p/DdyLrNpt3UU/ https://www.instagram.com/p/DdzcjsYtSxs/ 'A pump might be fun' https://www.instagram.com/p/DeAn0u0Dc9M/ '$ABU Officially on Chain'
A7: Brigitte Macaron | B7: brigittemacaron_ | C7: https://www.instagram.com/brigittemacaron_/ | D7: =INDEX('ALL CANDIDATES'!$K$2:$K$63,MATCH($B7,'ALL CANDIDATES'!$C$2:$C$63,0)) -> 4299 | E7: =INDEX('ALL CANDIDATES'!$M$2:$M$63,MATCH($B7,'ALL CANDIDATES'!$C$2:$C$63,0)) -> 18 | F7: =INDEX('ALL CANDIDATES'!$W$2:$W$63,MATCH($B7,'ALL CANDIDATES'!$C$2:$C$63,0)) -> 9 | G7: =INDEX('ALL CANDIDATES'!$T$2:$T$63,MATCH($B7,'ALL CANDIDATES'!$C$2:$C$63,0)) -> 7 | H7: =INDEX('ALL CANDIDATES'!$X$2:$X$63,MATCH($B7,'ALL CANDIDATES'!$C$2:$C$63,0)) -> 6938 | I7: =INDEX('ALL CANDIDATES'!$Z$2:$Z$63,MATCH($B7,'ALL CANDIDATES'!$C$2:$C$63,0)) -> 14 | J7: =INDEX('ALL CANDIDATES'!$AC$2:$AC$63,MATCH($B7,'ALL CANDIDATES'!$C$2:$C$63,0)) -> 1.6171203 | K7: =INDEX('ALL CANDIDATES'!$AD$2:$AD$63,MATCH($B7,'ALL CANDIDATES'!$C$2:$C$63,0)) -> Very high | L7: =INDEX('ALL CANDIDATES'!$R$2:$R$63,MATCH($B7,'ALL CANDIDATES'!$C$2:$C$63,0)) -> 46303 | M7: OBSERVED: last post 2026-10-08 ('Public transport. Private concert 🫦'). 7 posts in 7 days; likes hidden on most posts; comments 1-21 per post. | N7: OBSERVED: first post 2026-09-26 - 'Dua couldn't make it. I was two stops away' (4,911 likes / 62 comments). Full history (18/18) loaded. | O7: OBSERVED (bio verbatim): TikTok: brigittemacaron_ (300K) / Tomorrow's outfit. I'm letting you decide 👇🏻 | P7: OBSERVED: calls fans 'Macaronies'; 'Your father insisted...', 'They challenged the wrong auntie 💅'. INFERRED: flirtatious, fashion-obsessed Parisian matriarch, implied partner of Jean Phil | Q7: OBSERVED: platinum blunt bob, tortoiseshell glasses, red patent jacket / Spider-Man suit outfits, pastries; metro and cafe settings | R7: OBSERVED: 18/18 Reels; 'vote on tomorrow's outfit' interactive format | S7: OBSERVED: outfit voting; Fashion Week (Milan, Paris); Dua Lipa obsession; Jean Phil family references ('La Jeanconde. My greatest masterpiece') | T7: OBSERVED: 1) https://www.instagram.com/p/DeEZ0sEN_Hy/ 2026-10-04 '200K Macaronies on TikTok, in less than 1 week' - 17,442 likes / 91 comments; 2) https://www.instagram.com/p/DdwN0y8t_Xg/ 09-26 - 4,911 / 62; other posts' likes hidden (UNKNOWN). | U7: OBSERVED: https://www.instagram.com/p/Dd6t_drNhuS/ 'La Jeanconde. My greatest masterpiece (so far) 🎨'; https://www.instagram.com/p/Dd6B7oYNEhb/ 'My first Fashion Week. Your father insisted…'; https://www.instagram.com/p/DeKGJoIN3vK/ outfit-vote result ('Apparently I'm Spider…' - 18 comments). 18/18 Reels. | V7: OBSERVED: self-reported '200K Macaronies on TikTok in less than 1 week' (10-04) and 'TikTok: brigittemacaron_ (300K)' in bio. External (non-IG): Sprites.ai cites 16M views in 3 days (creator thread). IG reach itself is modest. | W7: UNKNOWN - Dua Lipa is tagged as a joke, not a partner | X7: OBSERVED: OUT -> @jean_philanthrope (4; implied family - 'La Jeanconde', 'Your father'). Also tags @dualipa (real singer) as a joke. | Y7: OBSERVED: NONE on this account. Copycat @brigitte_macaron_ (268 followers) shows '$MACARON' | Z7: $MADAME | AA7: UNKNOWN | AB7: brigittemacaron.com | AC7: YES - OBSERVED last post 2026-10-08. | AD7: INFERRED: First female lead of the wave and the only one with an interactive audience mechanic (outfit votes); IG is a secondary channel to TikTok. | AE7: PARODY name of a real public figure (Brigitte Macron). This is an AI character, NOT the real person; no affiliation shown. Reputational/legal risk for an index using the name. | AF7: @brigitte_macaron_ (268 followers, '$MACARON', copycat - EXCLUDED); @brigittemacaron__ (298, 1 post); @_brigitte._.macaron_ ('Gone'). | AG7: =INDEX('ALL CANDIDATES'!$BJ$2:$BJ$63,MATCH($B7,'ALL CANDIDATES'!$C$2:$C$63,0)) -> 33.8 | AH7: =INDEX('ALL CANDIDATES'!$BP$2:$BP$63,MATCH($B7,'ALL CANDIDATES'!$C$2:$C$63,0)) -> 52 | AI7: =INDEX('ALL CANDIDATES'!$BS$2:$BS$63,MATCH($B7,'ALL CANDIDATES'!$C$2:$C$63,0)) -> 51.9 | AJ7: https://www.instagram.com/p/DdwN0y8t_Xg/ debut https://www.instagram.com/p/DeEZ0sEN_Hy/ top (TikTok milestone) https://www.instagram.com/p/Dd6t_drNhuS/ 'La Jeanconde' https://www.instagram.com/p/Dd6B7oYNEhb/ Fashion Week
A8: Bill Smith Prince | B8: bill_smith_prince | C8: https://www.instagram.com/bill_smith_prince/ | D8: =INDEX('ALL CANDIDATES'!$K$2:$K$63,MATCH($B8,'ALL CANDIDATES'!$C$2:$C$63,0)) -> 15092 | E8: =INDEX('ALL CANDIDATES'!$M$2:$M$63,MATCH($B8,'ALL CANDIDATES'!$C$2:$C$63,0)) -> 12 | F8: =INDEX('ALL CANDIDATES'!$W$2:$W$63,MATCH($B8,'ALL CANDIDATES'!$C$2:$C$63,0)) -> 3.5 | G8: =INDEX('ALL CANDIDATES'!$T$2:$T$63,MATCH($B8,'ALL CANDIDATES'!$C$2:$C$63,0)) -> 0 | H8: =INDEX('ALL CANDIDATES'!$X$2:$X$63,MATCH($B8,'ALL CANDIDATES'!$C$2:$C$63,0)) -> 13819 | I8: =INDEX('ALL CANDIDATES'!$Z$2:$Z$63,MATCH($B8,'ALL CANDIDATES'!$C$2:$C$63,0)) -> 1015 | J8: =INDEX('ALL CANDIDATES'!$AC$2:$AC$63,MATCH($B8,'ALL CANDIDATES'!$C$2:$C$63,0)) -> 0.98290485 | K8: =INDEX('ALL CANDIDATES'!$AD$2:$AD$63,MATCH($B8,'ALL CANDIDATES'!$C$2:$C$63,0)) -> Very high | L8: =INDEX('ALL CANDIDATES'!$R$2:$R$63,MATCH($B8,'ALL CANDIDATES'!$C$2:$C$63,0)) -> 46297 | M8: OBSERVED: last post 2026-10-02; 0 posts in the 7 days before capture. Recent posts ~1-9K likes vs ~30K average before 09-25. | N8: OBSERVED: earliest post dated 2026-09-22 (full 12/12 history loaded; e.g. 'Sorry not sorry you are still early #boxer'). | O8: OBSERVED (bio verbatim): Official $BillSmith / Ca:zYiF3rA8aWYUuDek3Z3po9NF4V5UDky5nji7Wr6pump / Made with @higgsfield.ai | P8: OBSERVED: 'If you cross me hold your cross very tight', 'Sorry not sorry you are still early #boxer'. INFERRED: menacing-but-fashionable boxer, crypto-shill voice ('you are still early') | Q8: OBSERVED: long white-blond hair, pale skin, burgundy suit + tie; street and phone-review clips | R8: OBSERVED: 9 Reels + 3 other | S8: OBSERVED: boxing/gang hashtags; Gucci suit jokes; 'still early' crypto phrasing | T8: OBSERVED: 1) https://www.instagram.com/p/Ddqo1FvtNyH/ 2026-09-24 'No way he will survive this @gucci make me a new suit…' - 52,286 likes / 1,767 comments; 2) https://www.instagram.com/p/DdoPdKptxDF/ 09-23 'If you cross me hold your cross very tight' - 48,274 / 7,122; 3) https://www.instagram.com/p/DdmSujhN2mt/ 09-22 'Sorry not sorry you are still early' - 47,869 / 2,719 | U8: OBSERVED: the three posts above are Reels; https://www.instagram.com/p/DdtyIBLt2oE/ 09-25 9,256 (best in last 14 days). 9 Reels of 12 posts. | V8: OBSERVED: 7,122 comments on one reel (09-23) - highest comments-per-follower of any seed. No 100K+ post. | W8: UNKNOWN - Gucci tagged, no partnership label | X8: OBSERVED: none (only @gucci and @demna - brand/real designer). | Y8: OBSERVED: $BillSmith + Solana contract address (…pump) in bio | Z8: $FRESHBILL | AA8: UNKNOWN | AB8: (none) | AC8: SLOWING - OBSERVED last post 2026-10-02 (7 days before capture). | AD8: INFERRED: Clearest 'character-as-token-wrapper' case: contract address in bio from day one; small audience but high comment counts on early posts (7,122 on one reel). | AE8: Original fictional character; name not tied to an identified real person. | AF8: UNKNOWN - no copycats found in search ('bill smith' search returns unrelated real people incl. @willsmith). | AG8: =INDEX('ALL CANDIDATES'!$BJ$2:$BJ$63,MATCH($B8,'ALL CANDIDATES'!$C$2:$C$63,0)) -> 36.9 | AH8: =INDEX('ALL CANDIDATES'!$BP$2:$BP$63,MATCH($B8,'ALL CANDIDATES'!$C$2:$C$63,0)) -> 39 | AI8: =INDEX('ALL CANDIDATES'!$BS$2:$BS$63,MATCH($B8,'ALL CANDIDATES'!$C$2:$C$63,0)) -> 45.1 | AJ8: https://www.instagram.com/p/DdmSujhN2mt/ early https://www.instagram.com/p/DdoPdKptxDF/ https://www.instagram.com/p/Ddqo1FvtNyH/ top (Gucci joke) https://www.instagram.com/p/DdtyIBLt2oE/
A10: Legend: OBSERVED = seen on Instagram; INFERRED = analyst interpretation; UNKNOWN = not verifiable on Instagram. Green numbers are live links to ALL CANDIDATES. Snapshot 2026-10-09.

Sheet ALL CANDIDATES
A1: ID | B1: Name | C1: Handle | D1: Profile URL | E1: Group | F1: Inclusion status | G1: Status reason / caveat | H1: Character type | I1: Origin / wave | J1: Verified badge (Y/N) | K1: Followers | L1: Following | M1: Posts (media count) | N1: Posts analysed | O1: Full history loaded? | P1: First visible post date | Q1: First-date basis | R1: Last post date | S1: Days since last post | T1: Posts last 7d | U1: Posts last 14d | V1: Posts last 30d | W1: Posting freq (posts/week, 14d) | X1: Avg likes (last 12) | Y1: Median likes (last 12) | Z1: Avg comments (last 12) | AA1: Median comments (last 12) | AB1: Likes hidden (of last 12) | AC1: Engagement rate | AD1: Engagement level | AE1: Avg likes (14d) | AF1: Avg comments (14d) | AG1: Max likes (analysed posts) | AH1: Top post URL | AI1: Top post date | AJ1: Top post comments | AK1: Top post caption / note | AL1: Top 14d post likes | AM1: Top 14d post URL | AN1: Top 14d post date | AO1: Bio (verbatim) | AP1: Link in bio | AQ1: Ticker / token - Instagram observed | AR1: Ticker - user supplied | AS1: Ticker - external (non-IG) | AT1: Related accounts (IG tags / mentions, count) | AU1: Personality / archetype | AV1: Visual style | AW1: Content format | AX1: Notes / evidence | AY1: INPUT Recognizability (0-5) | AZ1: INPUT Distinct: visual (0-5) | BA1: INPUT Distinct: personality (0-5) | BB1: INPUT Distinct: lore (0-5) | BC1: INPUT Distinct: cross-character (0-5) | BD1: F: followers (0-1) | BE1: F: engagement (0-1) | BF1: F: viral (0-1) | BG1: F: consistency (0-1) | BH1: F: longevity (0-1) | BI1: F: recognizability (0-1) | BJ1: FAME SCORE (0-100) | BK1: M: recent engagement (0-1) | BL1: M: recent viral (0-1) | BM1: M: frequency (0-1) | BN1: M: growth (0-1) | BO1: M: recency (0-1) | BP1: MOMENTUM SCORE (0-100) | BQ1: DISTINCTIVENESS SCORE (0-100) | BR1: Data sufficiency (0-1) | BS1: INDEX CANDIDATE SCORE (0-100) | BT1: rank key: fame | BU1: rank key: momentum | BV1: rank key: distinct | BW1: rank key: index | BX1: Why it matters
A2: 1 | B2: Jean Phil | C2: jean_philanthrope | D2: https://www.instagram.com/jean_philanthrope/ | E2: SEED | F2: INCLUDED | H2: Parody French gentleman-boxer (AI-generated human character) | I2: Sep-2026 AI character / memecoin wave | J2: N | K2: 241147 | L2: 1 | M2: 12 | N2: 12 | O2: YES (12/12) | P2: 46282 | Q2: Full history loaded - first post | R2: 46302 | S2: =IF(R2="","",'SCORING METHOD'!$C$5-R2) -> 2 | T2: 2 | U2: 4 | V2: 12 | W2: =IF(U2="","",U2/2) -> 2 | X2: 297994 | Y2: 110763 | Z2: 7823 | AA2: 2980 | AB2: 0 | AC2: =IF(OR(X2="",K2="",K2=0),"",(X2+N(Z2))/K2) -> 1.2681767 | AD2: =IF(AC2="","UNKNOWN",IF(AC2>=0.05,"Very high",IF(AC2>=0.02,"High",IF(AC2>=0.005,"Medium","Low")))) -> Very high | AE2: 11876 | AF2: 613 | AG2: 1708185 | AH2: https://www.instagram.com/p/Ddb0QUyqnhG/ | AI2: 46284 | AJ2: 53119 | AK2: Elle m'appelle le soir, elle t'appelle bout d'chou | AL2: 23808 | AM2: https://www.instagram.com/p/Ddy7hfsiPyt/ | AN2: 46292 | AO2: Oui Madame. | AP2: (none) - story highlight 'Contact' | AQ2: NONE observed in bio/captions | AR2: $JEAN | AS2: $JEANPHIL (pump.fun, Solana) per Dexerto/Sprites.ai - NOT on IG profile | AT2: IN: archibald_brown (9 mentions, rivalry), brigittemacaron_ (4), imranpoppadumb (4), derek.mercer.2006 (2), dequavious_von (2), jadeorlhabit_ (bio 'Love U'), brigitte_macaron_ (2). OUT: stellamccartney (2, brand), lafeve7 (2, real rapper - music) | AU2: OBSERVED: catchphrase 'Oui Madame.'; French captions; shadowboxing ('Jab, crochet. T'as senti le danger?'). INFERRED: suave, deadpan French gentleman-fighter / ladies' man | AV2: OBSERVED (grid screenshot): blond bowl/bob haircut, curled moustache, freckles, brown tweed suit + tie; real-world Paris locations | AW2: OBSERVED: 12/12 Reels; short vertical clips, French-language captions, music-driven | AX2: Debut 2026-09-17; peak 09-18..09-22 (two reels with 921K and 1.71M likes); October posts 6-9K likes. 'jeanphilanthrope.co' (250K followers, 'Evil Twin') is a separate promo/copycat account - EXCLUDED. | AY2: 5 | AZ2: 5 | BA2: 5 | BB2: 4 | BC2: 5 | BD2: =IF(K2="",0,MAX(0,MIN(1,(LOG10(MAX(1,K2))-3)/4))) -> 0.59557047 | BE2: =IF(X2="",0,MAX(0,MIN(1,(LOG10(MAX(1,X2))-2)/4))) -> 0.86855188 | BF2: =IF(AG2="",0,MAX(0,MIN(1,(LOG10(MAX(1,AG2))-3)/4))) -> 0.80813373 | BG2: =IF(V2="",0,MIN(1,V2/20)) -> 0.6 | BH2: =MAX(IF(P2="",0,MIN(1,('SCORING METHOD'!$C$5-P2)/730)),IF(M2="",0,MAX(0,MIN(1,(LOG10(MAX(1,M2))-1)/2.5)))) -> 0.031672498 | BI2: =IF(J2="Y",0.4,0)+0.6*N(AY2)/5 -> 0.6 | BJ2: =ROUND(BD2*'SCORING METHOD'!$C$6+BE2*'SCORING METHOD'!$C$7+BF2*'SCORING METHOD'!$C$8+BG2*'SCORING METHOD'!$C$9+BH2*'SCORING METHOD'!$C$10+BI2*'SCORING METHOD'!$C$11,1) -> 63.7 | BK2: =IF(AE2="",0,MAX(0,MIN(1,(LOG10(MAX(1,IF(X2="",AE2,MIN(AE2,X2))))-2)/4))) -> 0.51866755 | BL2: =IF(AL2="",0,MAX(0,MIN(1,(LOG10(MAX(1,AL2))-3)/4))) -> 0.34418073 | BM2: =IF(U2="",0,MIN(1,U2/14)) -> 0.28571429 | BN2: =IF(OR(P2="",K2="",N2="",M2="",M2=0),0,IF(AND('SCORING METHOD'!$C$5-P2<=60,N2/M2>=0.5),MAX(0,MIN(1,(LOG10(MAX(1,K2/MAX(1,'SCORING METHOD'!$C$5-P2)))-2)/2.5)),0)) -> 0.81594367 | BO2: =IF(S2="",0,MAX(0,MIN(1,1-(S2-3)/27))) -> 1 | BP2: =ROUND(BK2*'SCORING METHOD'!$C$12+BL2*'SCORING METHOD'!$C$13+BM2*'SCORING METHOD'!$C$14+BN2*'SCORING METHOD'!$C$15+BO2*'SCORING METHOD'!$C$16,1) -> 53.3 | BQ2: =ROUND((N(AZ2)+N(BA2)+N(BB2)+N(BC2))/20*100,1) -> 95 | BR2: =IFERROR(INDEX('DATA SUFFICIENCY'!$J$2:$J$63,MATCH(C2,'DATA SUFFICIENCY'!$B$2:$B$63,0)),0) -> 1 | BS2: =ROUND('SCORING METHOD'!$C$17*BJ2+'SCORING METHOD'!$C$18*BP2+'SCORING METHOD'!$C$19*BQ2+'SCORING METHOD'!$C$20*BR2*100,1) -> 72.3 | BT2: =IF(F2="INCLUDED",BJ2+(1000-ROW())/100000,-1) -> 63.70998 | BU2: =IF(F2="INCLUDED",BP2+(1000-ROW())/100000,-1) -> 53.30998 | BV2: =IF(F2="INCLUDED",BQ2+(1000-ROW())/100000,-1) -> 95.00998 | BW2: =IF(F2="INCLUDED",BS2+(1000-ROW())/100000,-1) -> 72.30998 | BX2: Patient zero of the Sep-2026 AI-character wave: 1.7M-like reel within 2 days of debut; the hub most other characters tag or call out.
A3: 2 | B3: Benjamin Stachio | C3: benjamin_stachio | D3: https://www.instagram.com/benjamin_stachio/ | E3: SEED | F3: INCLUDED | H3: Absurd-proportion dancing gentleman (AI-generated human) | I3: Sep-2026 AI character / memecoin wave | J3: N | K3: 101097 | L3: 0 | M3: 15 | N3: 15 | O3: YES (15/15) | P3: 46292 | Q3: Full history loaded - first post | R3: 46303 | S3: =IF(R3="","",'SCORING METHOD'!$C$5-R3) -> 1 | T3: 6 | U3: 12 | V3: 12 | W3: =IF(U3="","",U3/2) -> 6 | X3: 8999 | Y3: 4168 | Z3: 575 | AA3: 166 | AB3: 0 | AC3: =IF(OR(X3="",K3="",K3=0),"",(X3+N(Z3))/K3) -> 0.094701129 | AD3: =IF(AC3="","UNKNOWN",IF(AC3>=0.05,"Very high",IF(AC3>=0.02,"High",IF(AC3>=0.005,"Medium","Low")))) -> Very high | AE3: 8999 | AF3: 575 | AG3: 846425 | AH3: https://www.instagram.com/p/Dd2joiwTDJv/ | AI3: 46294 | AJ3: 76277 | AK3: Dancing with friends (pinned) | AL3: 43249 | AM3: https://www.instagram.com/p/Dd4BE9nMR7M/ | AN3: 46294 | AO3: Hello Darling / ⚠️No crypto affiliation yet⚠️ | AP3: (none) | AQ3: NONE - bio explicitly says 'No crypto affiliation yet' | AR3: $STACHE | AS3: None per Dexerto (2026-09-30) | AT3: No fictional-character tags/mentions observed in 15 posts | AU3: OBSERVED: 'Hello Darling'; travel/dance diary captions ('Visiting Rio de Janeiro', 'Dressed for the meeting'). INFERRED: polite, oblivious party gentleman | AV3: OBSERVED: triple-curl hair swirl + huge curled moustache, oversized neck, white shirt, navy tie, mustard trousers; real-world crowds (bar, Rio, Washington Monument) | AW3: OBSERVED: 15/15 Reels; crowd-dance clips | AX3: Viral bar-dance reel 09-29 (846K likes / 76K comments; pinned). Pinned 10-07 post announces song 'Shut It' on streaming; 10-07 teaser 'Something big and fun is coming'. | AY3: 4 | AZ3: 5 | BA3: 4 | BB3: 3 | BC3: 1 | BD3: =IF(K3="",0,MAX(0,MIN(1,(LOG10(MAX(1,K3))-3)/4))) -> 0.50118457 | BE3: =IF(X3="",0,MAX(0,MIN(1,(LOG10(MAX(1,X3))-2)/4))) -> 0.48854856 | BF3: =IF(AG3="",0,MAX(0,MIN(1,(LOG10(MAX(1,AG3))-3)/4))) -> 0.73189712 | BG3: =IF(V3="",0,MIN(1,V3/20)) -> 0.6 | BH3: =MAX(IF(P3="",0,MIN(1,('SCORING METHOD'!$C$5-P3)/730)),IF(M3="",0,MAX(0,MIN(1,(LOG10(MAX(1,M3))-1)/2.5)))) -> 0.070436504 | BI3: =IF(J3="Y",0.4,0)+0.6*N(AY3)/5 -> 0.48 | BJ3: =ROUND(BD3*'SCORING METHOD'!$C$6+BE3*'SCORING METHOD'!$C$7+BF3*'SCORING METHOD'!$C$8+BG3*'SCORING METHOD'!$C$9+BH3*'SCORING METHOD'!$C$10+BI3*'SCORING METHOD'!$C$11,1) -> 50.9 | BK3: =IF(AE3="",0,MAX(0,MIN(1,(LOG10(MAX(1,IF(X3="",AE3,MIN(AE3,X3))))-2)/4))) -> 0.48854856 | BL3: =IF(AL3="",0,MAX(0,MIN(1,(LOG10(MAX(1,AL3))-3)/4))) -> 0.40899402 | BM3: =IF(U3="",0,MIN(1,U3/14)) -> 0.85714286 | BN3: =IF(OR(P3="",K3="",N3="",M3="",M3=0),0,IF(AND('SCORING METHOD'!$C$5-P3<=60,N3/M3>=0.5),MAX(0,MIN(1,(LOG10(MAX(1,K3/MAX(1,'SCORING METHOD'!$C$5-P3)))-2)/2.5)),0)) -> 0.77022281 | BO3: =IF(S3="",0,MAX(0,MIN(1,1-(S3-3)/27))) -> 1 | BP3: =ROUND(BK3*'SCORING METHOD'!$C$12+BL3*'SCORING METHOD'!$C$13+BM3*'SCORING METHOD'!$C$14+BN3*'SCORING METHOD'!$C$15+BO3*'SCORING METHOD'!$C$16,1) -> 61.7 | BQ3: =ROUND((N(AZ3)+N(BA3)+N(BB3)+N(BC3))/20*100,1) -> 65 | BR3: =IFERROR(INDEX('DATA SUFFICIENCY'!$J$2:$J$63,MATCH(C3,'DATA SUFFICIENCY'!$B$2:$B$63,0)),0) -> 0.7 | BS3: =ROUND('SCORING METHOD'!$C$17*BJ3+'SCORING METHOD'!$C$18*BP3+'SCORING METHOD'!$C$19*BQ3+'SCORING METHOD'!$C$20*BR3*100,1) -> 59.8 | BT3: =IF(F3="INCLUDED",BJ3+(1000-ROW())/100000,-1) -> 50.90997 | BU3: =IF(F3="INCLUDED",BP3+(1000-ROW())/100000,-1) -> 61.70997 | BV3: =IF(F3="INCLUDED",BQ3+(1000-ROW())/100000,-1) -> 65.00997 | BW3: =IF(F3="INCLUDED",BS3+(1000-ROW())/100000,-1) -> 59.80997 | BX3: Most visually distinctive body-horror-comedy design of the wave; first character to move into music (single 'Shut It').
A4: 3 | B4: Lord Farquaad (parody account) | C4: lord.farquaad.sol | D4: https://www.instagram.com/lord.farquaad.sol/ | E4: SEED | F4: INCLUDED | G4: Parody of a third-party fictional character (Shrek) - IP/brand risk for an index | H4: AI parody of an existing film character, trend-dancing | I4: Sep-2026 AI character / memecoin wave | J4: N | K4: 102526 | L4: 19 | M4: 57 | N4: 57 | O4: YES (57/57 on first pass) | P4: 46290 | Q4: Full history loaded - first post | R4: 46304 | S4: =IF(R4="","",'SCORING METHOD'!$C$5-R4) -> 0 | T4: 26 | U4: 51 | V4: 56 | W4: =IF(U4="","",U4/2) -> 25.5 | X4: 2389 | Y4: 1286 | Z4: 38 | AA4: 34 | AB4: 0 | AC4: =IF(OR(X4="",K4="",K4=0),"",(X4+N(Z4))/K4) -> 0.023672044 | AD4: =IF(AC4="","UNKNOWN",IF(AC4>=0.05,"Very high",IF(AC4>=0.02,"High",IF(AC4>=0.005,"Medium","Low")))) -> High | AE4: 25012 | AF4: 209 | AG4: 379725 | AH4: https://www.instagram.com/p/DdwhswgBSFq/ | AI4: 46291 | AJ4: 2844 | AK4: Feeling fresh | AL4: 379725 | AM4: https://www.instagram.com/p/DdwhswgBSFq/ | AN4: 46291 | AO4: Some of you may die, but that is a sacrifice I am willing to make / Email: lordfarquaadbusiness@gmail.com / Made with @higgsfield.ai | AP4: (none) | AQ4: NONE in bio/captions; handle suffix '.sol' suggests Solana link (INFERRED) | AR4: $SHORTKING | AS4: UNKNOWN | AT4: higgsfield.ai (7), higgsfield.creators (2), higgsfield.soul (1) - AI tool sponsor, not characters | AU4: OBSERVED: bio quotes the film villain's line; captions 'You buggin', 'Feeling fresh', 'Goodnight everyone (say it back)'. INFERRED: pompous tiny tyrant who loves TikTok dance trends | AV4: OBSERVED: black page-boy bob, burgundy medieval tunic/cape, filmed in modern settings (metro, night city) | AW4: OBSERVED: 57/57 Reels; trend-dance clips; ~3-4 posts/day | AX4: Peak week 09-24..30 (21 posts, avg 50,981 likes) -> 10-05..09 (16 posts, avg 4,870). NOT the DreamWorks character itself - fan/AI parody. | AY4: 3 | AZ4: 4 | BA4: 3 | BB4: 2 | BC4: 1 | BD4: =IF(K4="",0,MAX(0,MIN(1,(LOG10(MAX(1,K4))-3)/4))) -> 0.5027085 | BE4: =IF(X4="",0,MAX(0,MIN(1,(LOG10(MAX(1,X4))-2)/4))) -> 0.34455404 | BF4: =IF(AG4="",0,MAX(0,MIN(1,(LOG10(MAX(1,AG4))-3)/4))) -> 0.6448673 | BG4: =IF(V4="",0,MIN(1,V4/20)) -> 1 | BH4: =MAX(IF(P4="",0,MIN(1,('SCORING METHOD'!$C$5-P4)/730)),IF(M4="",0,MAX(0,MIN(1,(LOG10(MAX(1,M4))-1)/2.5)))) -> 0.30234994 | BI4: =IF(J4="Y",0.4,0)+0.6*N(AY4)/5 -> 0.36 | BJ4: =ROUND(BD4*'SCORING METHOD'!$C$6+BE4*'SCORING METHOD'!$C$7+BF4*'SCORING METHOD'!$C$8+BG4*'SCORING METHOD'!$C$9+BH4*'SCORING METHOD'!$C$10+BI4*'SCORING METHOD'!$C$11,1) -> 51.5 | BK4: =IF(AE4="",0,MAX(0,MIN(1,(LOG10(MAX(1,IF(X4="",AE4,MIN(AE4,X4))))-2)/4))) -> 0.34455404 | BL4: =IF(AL4="",0,MAX(0,MIN(1,(LOG10(MAX(1,AL4))-3)/4))) -> 0.6448673 | BM4: =IF(U4="",0,MIN(1,U4/14)) -> 1 | BN4: =IF(OR(P4="",K4="",N4="",M4="",M4=0),0,IF(AND('SCORING METHOD'!$C$5-P4<=60,N4/M4>=0.5),MAX(0,MIN(1,(LOG10(MAX(1,K4/MAX(1,'SCORING METHOD'!$C$5-P4)))-2)/2.5)),0)) -> 0.74588239 | BO4: =IF(S4="",0,MAX(0,MIN(1,1-(S4-3)/27))) -> 1 | BP4: =ROUND(BK4*'SCORING METHOD'!$C$12+BL4*'SCORING METHOD'!$C$13+BM4*'SCORING METHOD'!$C$14+BN4*'SCORING METHOD'!$C$15+BO4*'SCORING METHOD'!$C$16,1) -> 64.4 | BQ4: =ROUND((N(AZ4)+N(BA4)+N(BB4)+N(BC4))/20*100,1) -> 50 | BR4: =IFERROR(INDEX('DATA SUFFICIENCY'!$J$2:$J$63,MATCH(C4,'DATA SUFFICIENCY'!$B$2:$B$63,0)),0) -> 0.8 | BS4: =ROUND('SCORING METHOD'!$C$17*BJ4+'SCORING METHOD'!$C$18*BP4+'SCORING METHOD'!$C$19*BQ4+'SCORING METHOD'!$C$20*BR4*100,1) -> 59.3 | BT4: =IF(F4="INCLUDED",BJ4+(1000-ROW())/100000,-1) -> 51.50996 | BU4: =IF(F4="INCLUDED",BP4+(1000-ROW())/100000,-1) -> 64.40996 | BV4: =IF(F4="INCLUDED",BQ4+(1000-ROW())/100000,-1) -> 50.00996 | BW4: =IF(F4="INCLUDED",BS4+(1000-ROW())/100000,-1) -> 59.30996 | BX4: Highest posting cadence of any seed and an explicit AI-tool sponsorship - shows the brand-deal business model; borrowed IP limits index suitability.
A5: 4 | B5: Archibald Brown | C5: archibald_brown | D5: https://www.instagram.com/archibald_brown/ | E5: SEED | F5: INCLUDED | H5: British boxer / trash-talking rival (AI-generated human) | I5: Sep-2026 AI character / memecoin wave | J5: N | K5: 131892 | L5: 24 | M5: 56 | N5: 56 | O5: YES (56/56) | P5: 46285 | Q5: Full history loaded - first post | R5: 46302 | S5: =IF(R5="","",'SCORING METHOD'!$C$5-R5) -> 2 | T5: 5 | U5: 25 | V5: 53 | W5: =IF(U5="","",U5/2) -> 12.5 | X5: 1302 | Y5: 936 | Z5: 28 | AA5: 25 | AB5: 0 | AC5: =IF(OR(X5="",K5="",K5=0),"",(X5+N(Z5))/K5) -> 0.010084008 | AD5: =IF(AC5="","UNKNOWN",IF(AC5>=0.05,"Very high",IF(AC5>=0.02,"High",IF(AC5>=0.005,"Medium","Low")))) -> Medium | AE5: 2635 | AF5: 62 | AG5: 1106935 | AH5: https://www.instagram.com/p/DdmQOpyMNfr/ | AI5: 46287 | AJ5: 11486 | AK5: Send me a dm for coaching | AL5: 27193 | AM5: https://www.instagram.com/p/DdzwiRxMIMU/ | AN5: 46292 | AO5: DM if you need the 101 on throwing hands? 🥊 | AP5: archibaldbrown.com (+ Threads @archibald_brown) | AQ5: NONE observed | AR5: UNKNOWN | AS5: $ARCHIBROWN per Dexerto/Sprites.ai - NOT on IG profile | AT5: OUT: jean_philanthrope (9; rivalry), abunuttyofficial (3; 'you're next'), danawhite (3, real), anthonyjoshua (12, real), jonnybones (7, real), ___johnjones___ (5), miketyson (1, real), mighty (13, unknown). IN: percival_ashcrofttt (3) | AU5: OBSERVED: coaching/fight talk ('101 on throwing hands', 'Quick 101'), call-outs ('@jean_philanthrope come to London and find out…'). INFERRED: cocky London boxer, Jean Phil's nemesis | AV5: OBSERVED: chestnut bowl cut, thin moustache, beige suit + tie; pinned UFC-contract photo; staged photo with a Mike Tyson likeness | AW5: OBSERVED: 50 Reels + 6 photos/carousels; highlights 'Going pro', 'Getting him' | AX5: Tags real athletes for storyline - these are NOT endorsements. Peak pre-09-24 (18 posts avg 90,924 likes); October ~1-2K likes. | AY5: 4 | AZ5: 4 | BA5: 4 | BB5: 5 | BC5: 5 | BD5: =IF(K5="",0,MAX(0,MIN(1,(LOG10(MAX(1,K5))-3)/4))) -> 0.53005461 | BE5: =IF(X5="",0,MAX(0,MIN(1,(LOG10(MAX(1,X5))-2)/4))) -> 0.27865275 | BF5: =IF(AG5="",0,MAX(0,MIN(1,(LOG10(MAX(1,AG5))-3)/4))) -> 0.76103053 | BG5: =IF(V5="",0,MIN(1,V5/20)) -> 1 | BH5: =MAX(IF(P5="",0,MIN(1,('SCORING METHOD'!$C$5-P5)/730)),IF(M5="",0,MAX(0,MIN(1,(LOG10(MAX(1,M5))-1)/2.5)))) -> 0.29927521 | BI5: =IF(J5="Y",0.4,0)+0.6*N(AY5)/5 -> 0.48 | BJ5: =ROUND(BD5*'SCORING METHOD'!$C$6+BE5*'SCORING METHOD'!$C$7+BF5*'SCORING METHOD'!$C$8+BG5*'SCORING METHOD'!$C$9+BH5*'SCORING METHOD'!$C$10+BI5*'SCORING METHOD'!$C$11,1) -> 54.5 | BK5: =IF(AE5="",0,MAX(0,MIN(1,(LOG10(MAX(1,IF(X5="",AE5,MIN(AE5,X5))))-2)/4))) -> 0.27865275 | BL5: =IF(AL5="",0,MAX(0,MIN(1,(LOG10(MAX(1,AL5))-3)/4))) -> 0.35861428 | BM5: =IF(U5="",0,MIN(1,U5/14)) -> 1 | BN5: =IF(OR(P5="",K5="",N5="",M5="",M5=0),0,IF(AND('SCORING METHOD'!$C$5-P5<=60,N5/M5>=0.5),MAX(0,MIN(1,(LOG10(MAX(1,K5/MAX(1,'SCORING METHOD'!$C$5-P5)))-2)/2.5)),0)) -> 0.73658594 | BO5: =IF(S5="",0,MAX(0,MIN(1,1-(S5-3)/27))) -> 1 | BP5: =ROUND(BK5*'SCORING METHOD'!$C$12+BL5*'SCORING METHOD'!$C$13+BM5*'SCORING METHOD'!$C$14+BN5*'SCORING METHOD'!$C$15+BO5*'SCORING METHOD'!$C$16,1) -> 54.8 | BQ5: =ROUND((N(AZ5)+N(BA5)+N(BB5)+N(BC5))/20*100,1) -> 90 | BR5: =IFERROR(INDEX('DATA SUFFICIENCY'!$J$2:$J$63,MATCH(C5,'DATA SUFFICIENCY'!$B$2:$B$63,0)),0) -> 1 | BS5: =ROUND('SCORING METHOD'!$C$17*BJ5+'SCORING METHOD'!$C$18*BP5+'SCORING METHOD'!$C$19*BQ5+'SCORING METHOD'!$C$20*BR5*100,1) -> 68.5 | BT5: =IF(F5="INCLUDED",BJ5+(1000-ROW())/100000,-1) -> 54.50995 | BU5: =IF(F5="INCLUDED",BP5+(1000-ROW())/100000,-1) -> 54.80995 | BV5: =IF(F5="INCLUDED",BQ5+(1000-ROW())/100000,-1) -> 90.00995 | BW5: =IF(F5="INCLUDED",BS5+(1000-ROW())/100000,-1) -> 68.50995 | BX5: The storyline engine of the wave: rivalry with Jean Phil, cross-over call-outs to the AI-animal fighters (Abu Nutty, Casper). Strong lore, weak recent engagement.
A6: 5 | B6: Abu Shalab | C6: abu.shalab | D6: https://www.instagram.com/abu.shalab/ | E6: SEED | F6: INCLUDED | H6: Gulf-style dancing comedian (AI-generated human) | I6: Sep-2026 AI character / memecoin wave | J6: N | K6: 531003 | L6: 0 | M6: 27 | N6: 27 | O6: YES (27/27) | P6: 46290 | Q6: Full history loaded - first post | R6: 46303 | S6: =IF(R6="","",'SCORING METHOD'!$C$5-R6) -> 1 | T6: 11 | U6: 27 | V6: 27 | W6: =IF(U6="","",U6/2) -> 13.5 | X6: 22069 | Y6: 9664 | Z6: 578 | AA6: 437 | AB6: 0 | AC6: =IF(OR(X6="",K6="",K6=0),"",(X6+N(Z6))/K6) -> 0.042649477 | AD6: =IF(AC6="","UNKNOWN",IF(AC6>=0.05,"Very high",IF(AC6>=0.02,"High",IF(AC6>=0.005,"Medium","Low")))) -> High | AE6: 157239 | AF6: 4532 | AG6: 1392520 | AH6: https://www.instagram.com/p/Dduf1zGNri-/ | AI6: 46290 | AJ6: 16271 | AK6: Throwback to when i won red bull dance | AL6: 1392520 | AM6: https://www.instagram.com/p/Dduf1zGNri-/ | AN6: 46290 | AO6: Dancer | Actor | Comedian / Road to 1M followers 😁 (0.52/1M) / Official $ABU👇 | AP6: join.pump.fun/HSag/wsvnmbjs (pump.fun referral) | AQ6: $ABU (bio + 10-02 carousel '$ABU Officially on Chain 🚀') | AR6: $ABUJAB | AS6: UNKNOWN | AT6: IN: imranpoppadumb (2). No outbound character tags observed | AU6: OBSERVED: 'Dancer | Actor | Comedian'; emoji-only captions, 'Heeywa', 'Habibi got hands'. INFERRED: carefree uncle-dancer | AV6: OBSERVED: white thobe, black bob wig, thick moustache; Dubai skyline, cars, airplanes | AW6: OBSERVED: 26 Reels + 1 carousel | AX6: Largest seed by followers. First 5 days (09-25..29) produced 1.39M, 874K and 527K-like reels; October posts 1-81K likes. | AY6: 3 | AZ6: 5 | BA6: 4 | BB6: 2 | BC6: 1 | BD6: =IF(K6="",0,MAX(0,MIN(1,(LOG10(MAX(1,K6))-3)/4))) -> 0.68127424 | BE6: =IF(X6="",0,MAX(0,MIN(1,(LOG10(MAX(1,X6))-2)/4))) -> 0.58594566 | BF6: =IF(AG6="",0,MAX(0,MIN(1,(LOG10(MAX(1,AG6))-3)/4))) -> 0.78595036 | BG6: =IF(V6="",0,MIN(1,V6/20)) -> 1 | BH6: =MAX(IF(P6="",0,MIN(1,('SCORING METHOD'!$C$5-P6)/730)),IF(M6="",0,MAX(0,MIN(1,(LOG10(MAX(1,M6))-1)/2.5)))) -> 0.17254551 | BI6: =IF(J6="Y",0.4,0)+0.6*N(AY6)/5 -> 0.36 | BJ6: =ROUND(BD6*'SCORING METHOD'!$C$6+BE6*'SCORING METHOD'!$C$7+BF6*'SCORING METHOD'!$C$8+BG6*'SCORING METHOD'!$C$9+BH6*'SCORING METHOD'!$C$10+BI6*'SCORING METHOD'!$C$11,1) -> 63.2 | BK6: =IF(AE6="",0,MAX(0,MIN(1,(LOG10(MAX(1,IF(X6="",AE6,MIN(AE6,X6))))-2)/4))) -> 0.58594566 | BL6: =IF(AL6="",0,MAX(0,MIN(1,(LOG10(MAX(1,AL6))-3)/4))) -> 0.78595036 | BM6: =IF(U6="",0,MIN(1,U6/14)) -> 1 | BN6: =IF(OR(P6="",K6="",N6="",M6="",M6=0),0,IF(AND('SCORING METHOD'!$C$5-P6<=60,N6/M6>=0.5),MAX(0,MIN(1,(LOG10(MAX(1,K6/MAX(1,'SCORING METHOD'!$C$5-P6)))-2)/2.5)),0)) -> 1 | BO6: =IF(S6="",0,MAX(0,MIN(1,1-(S6-3)/27))) -> 1 | BP6: =ROUND(BK6*'SCORING METHOD'!$C$12+BL6*'SCORING METHOD'!$C$13+BM6*'SCORING METHOD'!$C$14+BN6*'SCORING METHOD'!$C$15+BO6*'SCORING METHOD'!$C$16,1) -> 80.2 | BQ6: =ROUND((N(AZ6)+N(BA6)+N(BB6)+N(BC6))/20*100,1) -> 60 | BR6: =IFERROR(INDEX('DATA SUFFICIENCY'!$J$2:$J$63,MATCH(C6,'DATA SUFFICIENCY'!$B$2:$B$63,0)),0) -> 0.9 | BS6: =ROUND('SCORING METHOD'!$C$17*BJ6+'SCORING METHOD'!$C$18*BP6+'SCORING METHOD'!$C$19*BQ6+'SCORING METHOD'!$C$20*BR6*100,1) -> 71.7 | BT6: =IF(F6="INCLUDED",BJ6+(1000-ROW())/100000,-1) -> 63.20994 | BU6: =IF(F6="INCLUDED",BP6+(1000-ROW())/100000,-1) -> 80.20994 | BV6: =IF(F6="INCLUDED",BQ6+(1000-ROW())/100000,-1) -> 60.00994 | BW6: =IF(F6="INCLUDED",BS6+(1000-ROW())/100000,-1) -> 71.70994 | BX6: Biggest audience among seeds (531K in 14 days) and the clearest IG-native token link ($ABU + pump.fun link in bio).
A7: 6 | B7: Brigitte Macaron | C7: brigittemacaron_ | D7: https://www.instagram.com/brigittemacaron_/ | E7: SEED | F7: INCLUDED | G7: Parody of a real public figure's name (Brigitte Macron) - NOT that person | H7: Parisian 'auntie' fashion persona (AI-generated human) | I7: Sep-2026 AI character / memecoin wave | J7: N | K7: 4299 | L7: 1 | M7: 18 | N7: 18 | O7: YES (18/18) | P7: 46291 | Q7: Full history loaded - first post | R7: 46303 | S7: =IF(R7="","",'SCORING METHOD'!$C$5-R7) -> 1 | T7: 7 | U7: 18 | V7: 18 | W7: =IF(U7="","",U7/2) -> 9 | X7: 6938 | Y7: 4911 | Z7: 14 | AA7: 5 | AB7: 11 | AC7: =IF(OR(X7="",K7="",K7=0),"",(X7+N(Z7))/K7) -> 1.6171203 | AD7: =IF(AC7="","UNKNOWN",IF(AC7>=0.05,"Very high",IF(AC7>=0.02,"High",IF(AC7>=0.005,"Medium","Low")))) -> Very high | AE7: 6938 | AF7: 63 | AG7: 17442 | AH7: https://www.instagram.com/p/DeEZ0sEN_Hy/ | AI7: 46299 | AJ7: 91 | AK7: 200K Macaronies on TikTok, in less than 1 week... | AL7: 17442 | AM7: https://www.instagram.com/p/DeEZ0sEN_Hy/ | AN7: 46299 | AO7: TikTok: brigittemacaron_ (300K) / Tomorrow's outfit. I'm letting you decide 👇🏻 | AP7: brigittemacaron.com | AQ7: NONE on this account. Copycat @brigitte_macaron_ (268 followers) shows '$MACARON' | AR7: $MADAME | AS7: UNKNOWN | AT7: OUT: jean_philanthrope (4; 'La Jeanconde', 'your father' lore), dualipa (3, real singer) | AU7: OBSERVED: calls fans 'Macaronies'; 'Your father insisted...', 'They challenged the wrong auntie 💅'. INFERRED: flirtatious, fashion-obsessed Parisian matriarch, implied partner of Jean Phil | AV7: OBSERVED: platinum blunt bob, tortoiseshell glasses, red patent jacket / Spider-Man suit outfits, pastries; metro and cafe settings | AW7: OBSERVED: 18/18 Reels; 'vote on tomorrow's outfit' interactive format | AX7: Likes are HIDDEN on 14/18 posts (API returns placeholder 3) -> avg likes uses the 4 visible posts. Main audience is TikTok (300K per bio). Two IG accounts exist: brigittemacaron_ (primary: website + TikTok link) and brigitte_macaron_ (copycat). | AY7: 3 | AZ7: 4 | BA7: 4 | BB7: 3 | BC7: 3 | BD7: =IF(K7="",0,MAX(0,MIN(1,(LOG10(MAX(1,K7))-3)/4))) -> 0.15834186 | BE7: =IF(X7="",0,MAX(0,MIN(1,(LOG10(MAX(1,X7))-2)/4))) -> 0.46030857 | BF7: =IF(AG7="",0,MAX(0,MIN(1,(LOG10(MAX(1,AG7))-3)/4))) -> 0.31039907 | BG7: =IF(V7="",0,MIN(1,V7/20)) -> 0.9 | BH7: =MAX(IF(P7="",0,MIN(1,('SCORING METHOD'!$C$5-P7)/730)),IF(M7="",0,MAX(0,MIN(1,(LOG10(MAX(1,M7))-1)/2.5)))) -> 0.102109 | BI7: =IF(J7="Y",0.4,0)+0.6*N(AY7)/5 -> 0.36 | BJ7: =ROUND(BD7*'SCORING METHOD'!$C$6+BE7*'SCORING METHOD'!$C$7+BF7*'SCORING METHOD'!$C$8+BG7*'SCORING METHOD'!$C$9+BH7*'SCORING METHOD'!$C$10+BI7*'SCORING METHOD'!$C$11,1) -> 33.8 | BK7: =IF(AE7="",0,MAX(0,MIN(1,(LOG10(MAX(1,IF(X7="",AE7,MIN(AE7,X7))))-2)/4))) -> 0.46030857 | BL7: =IF(AL7="",0,MAX(0,MIN(1,(LOG10(MAX(1,AL7))-3)/4))) -> 0.31039907 | BM7: =IF(U7="",0,MIN(1,U7/14)) -> 1 | BN7: =IF(OR(P7="",K7="",N7="",M7="",M7=0),0,IF(AND('SCORING METHOD'!$C$5-P7<=60,N7/M7>=0.5),MAX(0,MIN(1,(LOG10(MAX(1,K7/MAX(1,'SCORING METHOD'!$C$5-P7)))-2)/2.5)),0)) -> 0.20776964 | BO7: =IF(S7="",0,MAX(0,MIN(1,1-(S7-3)/27))) -> 1 | BP7: =ROUND(BK7*'SCORING METHOD'!$C$12+BL7*'SCORING METHOD'!$C$13+BM7*'SCORING METHOD'!$C$14+BN7*'SCORING METHOD'!$C$15+BO7*'SCORING METHOD'!$C$16,1) -> 52 | BQ7: =ROUND((N(AZ7)+N(BA7)+N(BB7)+N(BC7))/20*100,1) -> 70 | BR7: =IFERROR(INDEX('DATA SUFFICIENCY'!$J$2:$J$63,MATCH(C7,'DATA SUFFICIENCY'!$B$2:$B$63,0)),0) -> 0.7 | BS7: =ROUND('SCORING METHOD'!$C$17*BJ7+'SCORING METHOD'!$C$18*BP7+'SCORING METHOD'!$C$19*BQ7+'SCORING METHOD'!$C$20*BR7*100,1) -> 51.9 | BT7: =IF(F7="INCLUDED",BJ7+(1000-ROW())/100000,-1) -> 33.80993 | BU7: =IF(F7="INCLUDED",BP7+(1000-ROW())/100000,-1) -> 52.00993 | BV7: =IF(F7="INCLUDED",BQ7+(1000-ROW())/100000,-1) -> 70.00993 | BW7: =IF(F7="INCLUDED",BS7+(1000-ROW())/100000,-1) -> 51.90993 | BX7: First female lead of the wave and the only one with an interactive audience mechanic (outfit votes); IG is a secondary channel to TikTok.
A8: 7 | B8: Bill Smith Prince | C8: bill_smith_prince | D8: https://www.instagram.com/bill_smith_prince/ | E8: SEED | F8: INCLUDED | H8: Platinum-haired boxing 'prince' / fashion gangster (AI-generated human) | I8: Sep-2026 AI character / memecoin wave | J8: N | K8: 15092 | L8: 1 | M8: 12 | N8: 12 | O8: YES (12/12) | P8: 46287 | Q8: Full history loaded - first post | R8: 46297 | S8: =IF(R8="","",'SCORING METHOD'!$C$5-R8) -> 7 | T8: 0 | U8: 7 | V8: 12 | W8: =IF(U8="","",U8/2) -> 3.5 | X8: 13819 | Y8: 2046 | Z8: 1015 | AA8: 87 | AB8: 0 | AC8: =IF(OR(X8="",K8="",K8=0),"",(X8+N(Z8))/K8) -> 0.98290485 | AD8: =IF(AC8="","UNKNOWN",IF(AC8>=0.05,"Very high",IF(AC8>=0.02,"High",IF(AC8>=0.005,"Medium","Low")))) -> Very high | AE8: 1941 | AF8: 67 | AG8: 52286 | AH8: https://www.instagram.com/p/Ddqo1FvtNyH/ | AI8: 46289 | AJ8: 1767 | AK8: No way he will survive this @gucci make me a new suit... | AL8: 9256 | AM8: https://www.instagram.com/p/DdtyIBLt2oE/ | AN8: 46290 | AO8: Official $BillSmith / Ca:zYiF3rA8aWYUuDek3Z3po9NF4V5UDky5nji7Wr6pump / Made with @higgsfield.ai | AP8: (none) | AQ8: $BillSmith + Solana contract address (…pump) in bio | AR8: $FRESHBILL | AS8: UNKNOWN | AT8: OUT: gucci (5, brand), demna (1, real designer). No fictional-character tags | AU8: OBSERVED: 'If you cross me hold your cross very tight', 'Sorry not sorry you are still early #boxer'. INFERRED: menacing-but-fashionable boxer, crypto-shill voice ('you are still early') | AV8: OBSERVED: long white-blond hair, pale skin, burgundy suit + tie; street and phone-review clips | AW8: OBSERVED: 9 Reels + 3 other | AX8: No posts since 2026-10-02 (7 days at capture) -> cooling. Ticker on IG ($BillSmith) differs from the user-supplied $FRESHBILL. | AY8: 2 | AZ8: 4 | BA8: 3 | BB8: 2 | BC8: 1 | BD8: =IF(K8="",0,MAX(0,MIN(1,(LOG10(MAX(1,K8))-3)/4))) -> 0.2946867 | BE8: =IF(X8="",0,MAX(0,MIN(1,(LOG10(MAX(1,X8))-2)/4))) -> 0.53511915 | BF8: =IF(AG8="",0,MAX(0,MIN(1,(LOG10(MAX(1,AG8))-3)/4))) -> 0.42959635 | BG8: =IF(V8="",0,MIN(1,V8/20)) -> 0.6 | BH8: =MAX(IF(P8="",0,MIN(1,('SCORING METHOD'!$C$5-P8)/730)),IF(M8="",0,MAX(0,MIN(1,(LOG10(MAX(1,M8))-1)/2.5)))) -> 0.031672498 | BI8: =IF(J8="Y",0.4,0)+0.6*N(AY8)/5 -> 0.24 | BJ8: =ROUND(BD8*'SCORING METHOD'!$C$6+BE8*'SCORING METHOD'!$C$7+BF8*'SCORING METHOD'!$C$8+BG8*'SCORING METHOD'!$C$9+BH8*'SCORING METHOD'!$C$10+BI8*'SCORING METHOD'!$C$11,1) -> 36.9 | BK8: =IF(AE8="",0,MAX(0,MIN(1,(LOG10(MAX(1,IF(X8="",AE8,MIN(AE8,X8))))-2)/4))) -> 0.32200638 | BL8: =IF(AL8="",0,MAX(0,MIN(1,(LOG10(MAX(1,AL8))-3)/4))) -> 0.24160584 | BM8: =IF(U8="",0,MIN(1,U8/14)) -> 0.5 | BN8: =IF(OR(P8="",K8="",N8="",M8="",M8=0),0,IF(AND('SCORING METHOD'!$C$5-P8<=60,N8/M8>=0.5),MAX(0,MIN(1,(LOG10(MAX(1,K8/MAX(1,'SCORING METHOD'!$C$5-P8)))-2)/2.5)),0)) -> 0.37931915 | BO8: =IF(S8="",0,MAX(0,MIN(1,1-(S8-3)/27))) -> 0.85185185 | BP8: =ROUND(BK8*'SCORING METHOD'!$C$12+BL8*'SCORING METHOD'!$C$13+BM8*'SCORING METHOD'!$C$14+BN8*'SCORING METHOD'!$C$15+BO8*'SCORING METHOD'!$C$16,1) -> 39 | BQ8: =ROUND((N(AZ8)+N(BA8)+N(BB8)+N(BC8))/20*100,1) -> 50 | BR8: =IFERROR(INDEX('DATA SUFFICIENCY'!$J$2:$J$63,MATCH(C8,'DATA SUFFICIENCY'!$B$2:$B$63,0)),0) -> 0.7 | BS8: =ROUND('SCORING METHOD'!$C$17*BJ8+'SCORING METHOD'!$C$18*BP8+'SCORING METHOD'!$C$19*BQ8+'SCORING METHOD'!$C$20*BR8*100,1) -> 45.1 | BT8: =IF(F8="INCLUDED",BJ8+(1000-ROW())/100000,-1) -> 36.90992 | BU8: =IF(F8="INCLUDED",BP8+(1000-ROW())/100000,-1) -> 39.00992 | BV8: =IF(F8="INCLUDED",BQ8+(1000-ROW())/100000,-1) -> 50.00992 | BW8: =IF(F8="INCLUDED",BS8+(1000-ROW())/100000,-1) -> 45.10992 | BX8: Clearest 'character-as-token-wrapper' case: contract address in bio from day one; small audience but high comment counts on early posts (7,122 on one reel).
